{
    DataVersion: 3120,
    size: [10, 17, 9],
    data: [
        {pos: [0, 0, 5], state: "minecraft:water{level:8}"},
        {pos: [3, 0, 5], state: "minecraft:stone"},
        {pos: [0, 1, 5], state: "minecraft:water{level:8}"},
        {pos: [3, 1, 5], state: "create:zinc_ore"},
        {pos: [4, 1, 5], state: "minecraft:stone"},
        {pos: [0, 2, 5], state: "minecraft:water{level:8}"},
        {pos: [2, 2, 5], state: "minecraft:vine{east:true,north:false,south:false,up:false,west:false}"},
        {pos: [3, 2, 5], state: "minecraft:gravel"},
        {pos: [4, 2, 4], state: "minecraft:stone"},
        {pos: [4, 2, 5], state: "minecraft:stone"},
        {pos: [0, 3, 5], state: "minecraft:water{level:8}"},
        {pos: [2, 3, 5], state: "minecraft:vine{east:true,north:false,south:false,up:false,west:false}"},
        {pos: [3, 3, 4], state: "minecraft:iron_ore"},
        {pos: [3, 3, 5], state: "minecraft:gravel"},
        {pos: [4, 3, 3], state: "minecraft:stone"},
        {pos: [4, 3, 4], state: "minecraft:coal_ore"},
        {pos: [4, 3, 5], state: "minecraft:stone"},
        {pos: [0, 4, 5], state: "minecraft:water{level:8}"},
        {pos: [2, 4, 5], state: "minecraft:vine{east:true,north:false,south:false,up:false,west:false}"},
        {pos: [3, 4, 3], state: "minecraft:iron_ore"},
        {pos: [3, 4, 4], state: "minecraft:andesite"},
        {pos: [3, 4, 5], state: "minecraft:stone"},
        {pos: [4, 4, 3], state: "minecraft:andesite"},
        {pos: [4, 4, 4], state: "minecraft:stone"},
        {pos: [4, 4, 5], state: "minecraft:iron_ore"},
        {pos: [5, 4, 4], state: "minecraft:cobweb"},
        {pos: [7, 4, 4], state: "minecraft:vine{east:false,north:false,south:false,up:false,west:true}"},
        {pos: [0, 5, 5], state: "minecraft:water{level:8}"},
        {pos: [2, 5, 2], state: "minecraft:vine{east:false,north:false,south:true,up:false,west:false}"},
        {pos: [2, 5, 4], state: "minecraft:diorite"},
        {pos: [2, 5, 5], state: "minecraft:vine{east:true,north:true,south:false,up:true,west:false}"},
        {pos: [3, 5, 3], state: "minecraft:andesite"},
        {pos: [3, 5, 4], state: "minecraft:andesite"},
        {pos: [3, 5, 5], state: "create:zinc_ore"},
        {pos: [4, 5, 2], state: "minecraft:stone"},
        {pos: [4, 5, 3], state: "minecraft:stone"},
        {pos: [4, 5, 4], state: "minecraft:lava{level:0}"},
        {pos: [4, 5, 5], state: "minecraft:iron_ore"},
        {pos: [4, 5, 6], state: "minecraft:cobweb"},
        {pos: [5, 5, 3], state: "minecraft:cobweb"},
        {pos: [5, 5, 4], state: "minecraft:coal_ore"},
        {pos: [7, 5, 4], state: "minecraft:vine{east:false,north:false,south:false,up:false,west:true}"},
        {pos: [0, 6, 5], state: "minecraft:water{level:8}"},
        {pos: [1, 6, 4], state: "minecraft:vine{east:false,north:false,south:false,up:true,west:false}"},
        {pos: [1, 6, 5], state: "minecraft:pointed_dripstone{thickness:tip,vertical_direction:down,waterlogged:false}"},
        {pos: [2, 6, 2], state: "minecraft:vine{east:false,north:false,south:true,up:true,west:false}"},
        {pos: [2, 6, 3], state: "minecraft:andesite"},
        {pos: [2, 6, 4], state: "minecraft:diorite"},
        {pos: [2, 6, 5], state: "minecraft:stone"},
        {pos: [3, 6, 2], state: "minecraft:diorite"},
        {pos: [3, 6, 3], state: "minecraft:andesite"},
        {pos: [3, 6, 4], state: "create:zinc_ore"},
        {pos: [3, 6, 5], state: "minecraft:andesite"},
        {pos: [3, 6, 6], state: "minecraft:pointed_dripstone{thickness:tip,vertical_direction:down,waterlogged:false}"},
        {pos: [4, 6, 2], state: "minecraft:stone"},
        {pos: [4, 6, 3], state: "minecraft:stone"},
        {pos: [4, 6, 4], state: "minecraft:bedrock"},
        {pos: [4, 6, 5], state: "minecraft:gravel"},
        {pos: [4, 6, 6], state: "minecraft:diorite"},
        {pos: [5, 6, 3], state: "minecraft:stone"},
        {pos: [5, 6, 4], state: "minecraft:gravel"},
        {pos: [7, 6, 4], state: "minecraft:vine{east:false,north:false,south:false,up:false,west:true}"},
        {pos: [0, 7, 5], state: "minecraft:water{level:8}"},
        {pos: [1, 7, 3], state: "minecraft:vine{east:false,north:false,south:true,up:false,west:false}"},
        {pos: [1, 7, 4], state: "minecraft:diorite"},
        {pos: [1, 7, 5], state: "minecraft:dripstone_block"},
        {pos: [1, 7, 6], state: "minecraft:pointed_dripstone{thickness:tip,vertical_direction:down,waterlogged:false}"},
        {pos: [2, 7, 2], state: "minecraft:clay"},
        {pos: [2, 7, 3], state: "minecraft:gravel"},
        {pos: [2, 7, 4], state: "minecraft:iron_ore"},
        {pos: [2, 7, 5], state: "minecraft:stone"},
        {pos: [2, 7, 6], state: "minecraft:pointed_dripstone{thickness:tip,vertical_direction:down,waterlogged:false}"},
        {pos: [3, 7, 2], state: "minecraft:diorite"},
        {pos: [3, 7, 3], state: "create:zinc_ore"},
        {pos: [3, 7, 4], state: "minecraft:iron_ore"},
        {pos: [3, 7, 5], state: "minecraft:andesite"},
        {pos: [3, 7, 6], state: "minecraft:dripstone_block"},
        {pos: [3, 7, 7], state: "minecraft:pointed_dripstone{thickness:tip,vertical_direction:down,waterlogged:false}"},
        {pos: [4, 7, 2], state: "minecraft:stone"},
        {pos: [4, 7, 3], state: "minecraft:stone"},
        {pos: [4, 7, 4], state: "minecraft:coal_ore"},
        {pos: [4, 7, 5], state: "minecraft:diorite"},
        {pos: [4, 7, 6], state: "minecraft:diorite"},
        {pos: [5, 7, 2], state: "minecraft:iron_ore"},
        {pos: [5, 7, 3], state: "minecraft:dirt"},
        {pos: [5, 7, 4], state: "minecraft:diorite"},
        {pos: [5, 7, 5], state: "minecraft:diorite"},
        {pos: [5, 7, 6], state: "minecraft:cobweb"},
        {pos: [6, 7, 4], state: "minecraft:dirt"},
        {pos: [7, 7, 4], state: "minecraft:vine{east:false,north:false,south:false,up:true,west:true}"},
        {pos: [0, 8, 4], state: "minecraft:vine{east:true,north:false,south:true,up:false,west:false}"},
        {pos: [0, 8, 5], state: "minecraft:water{level:1}"},
        {pos: [1, 8, 3], state: "minecraft:vine{east:false,north:false,south:true,up:true,west:false}"},
        {pos: [1, 8, 4], state: "minecraft:diorite"},
        {pos: [1, 8, 5], state: "minecraft:water{level:0}"},
        {pos: [1, 8, 6], state: "minecraft:dripstone_block"},
        {pos: [2, 8, 1], state: "minecraft:cobweb"},
        {pos: [2, 8, 2], state: "minecraft:clay"},
        {pos: [2, 8, 3], state: "minecraft:gravel"},
        {pos: [2, 8, 4], state: "minecraft:stone"},
        {pos: [2, 8, 5], state: "minecraft:stone"},
        {pos: [2, 8, 6], state: "minecraft:dripstone_block"},
        {pos: [3, 8, 1], state: "minecraft:dirt"},
        {pos: [3, 8, 2], state: "minecraft:clay"},
        {pos: [3, 8, 3], state: "minecraft:diorite"},
        {pos: [3, 8, 4], state: "minecraft:dirt"},
        {pos: [3, 8, 5], state: "minecraft:stone"},
        {pos: [3, 8, 6], state: "minecraft:lava{level:0}"},
        {pos: [3, 8, 7], state: "minecraft:dripstone_block"},
        {pos: [4, 8, 2], state: "minecraft:sand"},
        {pos: [4, 8, 3], state: "minecraft:dirt"},
        {pos: [4, 8, 4], state: "minecraft:stone"},
        {pos: [4, 8, 5], state: "minecraft:iron_ore"},
        {pos: [4, 8, 6], state: "minecraft:diorite"},
        {pos: [4, 8, 7], state: "minecraft:diorite"},
        {pos: [5, 8, 2], state: "minecraft:dirt"},
        {pos: [5, 8, 3], state: "minecraft:dirt"},
        {pos: [5, 8, 4], state: "minecraft:iron_ore"},
        {pos: [5, 8, 5], state: "minecraft:gravel"},
        {pos: [5, 8, 6], state: "minecraft:diorite"},
        {pos: [6, 8, 3], state: "minecraft:dirt"},
        {pos: [6, 8, 4], state: "minecraft:dirt"},
        {pos: [6, 8, 5], state: "minecraft:dirt"},
        {pos: [7, 8, 3], state: "minecraft:cobweb"},
        {pos: [7, 8, 4], state: "minecraft:dirt"},
        {pos: [0, 9, 4], state: "minecraft:vine{east:true,north:false,south:true,up:true,west:false}"},
        {pos: [0, 9, 5], state: "minecraft:dirt"},
        {pos: [1, 9, 3], state: "create:zinc_ore"},
        {pos: [1, 9, 4], state: "minecraft:diorite"},
        {pos: [1, 9, 5], state: "minecraft:stone"},
        {pos: [1, 9, 6], state: "minecraft:diorite"},
        {pos: [2, 9, 1], state: "minecraft:grass_block{snowy:false}"},
        {pos: [2, 9, 2], state: "minecraft:dirt"},
        {pos: [2, 9, 3], state: "minecraft:stone"},
        {pos: [2, 9, 4], state: "minecraft:iron_ore"},
        {pos: [2, 9, 5], state: "minecraft:diorite"},
        {pos: [2, 9, 6], state: "minecraft:diorite"},
        {pos: [3, 9, 1], state: "minecraft:dirt"},
        {pos: [3, 9, 2], state: "minecraft:dirt"},
        {pos: [3, 9, 3], state: "minecraft:iron_ore"},
        {pos: [3, 9, 4], state: "minecraft:dirt"},
        {pos: [3, 9, 5], state: "minecraft:diorite"},
        {pos: [3, 9, 6], state: "minecraft:dripstone_block"},
        {pos: [3, 9, 7], state: "minecraft:diorite"},
        {pos: [3, 9, 8], state: "minecraft:cobweb"},
        {pos: [4, 9, 1], state: "minecraft:dirt"},
        {pos: [4, 9, 2], state: "minecraft:sand"},
        {pos: [4, 9, 3], state: "minecraft:sand"},
        {pos: [4, 9, 4], state: "minecraft:clay"},
        {pos: [4, 9, 5], state: "minecraft:diorite"},
        {pos: [4, 9, 6], state: "minecraft:dirt"},
        {pos: [4, 9, 7], state: "minecraft:dirt"},
        {pos: [5, 9, 2], state: "minecraft:dirt"},
        {pos: [5, 9, 3], state: "minecraft:dirt"},
        {pos: [5, 9, 4], state: "minecraft:gravel"},
        {pos: [5, 9, 6], state: "minecraft:dirt"},
        {pos: [6, 9, 2], state: "minecraft:grass_block{snowy:false}"},
        {pos: [6, 9, 3], state: "minecraft:dirt"},
        {pos: [6, 9, 4], state: "minecraft:dirt"},
        {pos: [6, 9, 5], state: "minecraft:dirt"},
        {pos: [7, 9, 3], state: "minecraft:grass_block{snowy:false}"},
        {pos: [7, 9, 4], state: "minecraft:dirt"},
        {pos: [7, 9, 5], state: "minecraft:grass_block{snowy:false}"},
        {pos: [0, 10, 3], state: "minecraft:cobweb"},
        {pos: [0, 10, 4], state: "minecraft:dirt"},
        {pos: [0, 10, 5], state: "minecraft:dirt"},
        {pos: [1, 10, 3], state: "minecraft:dirt"},
        {pos: [1, 10, 4], state: "minecraft:dirt"},
        {pos: [1, 10, 5], state: "minecraft:stone"},
        {pos: [1, 10, 6], state: "minecraft:iron_ore"},
        {pos: [1, 10, 7], state: "minecraft:stone"},
        {pos: [2, 10, 2], state: "minecraft:grass_block{snowy:false}"},
        {pos: [2, 10, 3], state: "minecraft:dirt"},
        {pos: [2, 10, 4], state: "minecraft:grass_block{snowy:false}"},
        {pos: [2, 10, 5], state: "minecraft:grass_block{snowy:false}"},
        {pos: [2, 10, 6], state: "minecraft:dirt"},
        {pos: [2, 10, 7], state: "minecraft:diorite"},
        {pos: [2, 10, 8], state: "minecraft:dirt"},
        {pos: [3, 10, 1], state: "minecraft:grass_block{snowy:false}"},
        {pos: [3, 10, 2], state: "minecraft:grass_block{snowy:false}"},
        {pos: [3, 10, 3], state: "minecraft:grass_block{snowy:false}"},
        {pos: [3, 10, 4], state: "minecraft:farmland{moisture:7}"},
        {pos: [3, 10, 5], state: "minecraft:grass_block{snowy:false}"},
        {pos: [3, 10, 6], state: "minecraft:grass_block{snowy:false}"},
        {pos: [3, 10, 7], state: "minecraft:dirt"},
        {pos: [3, 10, 8], state: "minecraft:grass_block{snowy:false}"},
        {pos: [4, 10, 0], state: "minecraft:grass_block{snowy:false}"},
        {pos: [4, 10, 1], state: "minecraft:grass_block{snowy:false}"},
        {pos: [4, 10, 2], state: "minecraft:grass_block{snowy:false}"},
        {pos: [4, 10, 3], state: "minecraft:farmland{moisture:7}"},
        {pos: [4, 10, 4], state: "minecraft:water{level:0}"},
        {pos: [4, 10, 5], state: "minecraft:farmland{moisture:7}"},
        {pos: [4, 10, 6], state: "minecraft:grass_block{snowy:false}"},
        {pos: [4, 10, 7], state: "minecraft:grass_block{snowy:false}"},
        {pos: [5, 10, 1], state: "minecraft:grass_block{snowy:false}"},
        {pos: [5, 10, 2], state: "minecraft:grass_block{snowy:false}"},
        {pos: [5, 10, 3], state: "minecraft:grass_block{snowy:false}"},
        {pos: [5, 10, 4], state: "minecraft:farmland{moisture:7}"},
        {pos: [5, 10, 5], state: "minecraft:grass_block{snowy:false}"},
        {pos: [5, 10, 6], state: "minecraft:grass_block{snowy:false}"},
        {pos: [6, 10, 2], state: "minecraft:grass"},
        {pos: [6, 10, 3], state: "minecraft:grass_block{snowy:false}"},
        {pos: [6, 10, 4], state: "minecraft:grass_block{snowy:false}"},
        {pos: [6, 10, 5], state: "minecraft:grass_block{snowy:false}"},
        {pos: [7, 10, 3], state: "minecraft:tall_grass{half:lower}"},
        {pos: [7, 10, 4], state: "minecraft:dirt"},
        {pos: [0, 11, 3], state: "minecraft:cobweb"},
        {pos: [0, 11, 4], state: "minecraft:grass_block{snowy:false}"},
        {pos: [0, 11, 5], state: "minecraft:dirt"},
        {pos: [0, 11, 6], state: "minecraft:dirt"},
        {pos: [1, 11, 3], state: "minecraft:dirt"},
        {pos: [1, 11, 4], state: "minecraft:grass_block{snowy:false}"},
        {pos: [1, 11, 5], state: "minecraft:grass_block{snowy:false}"},
        {pos: [1, 11, 6], state: "minecraft:iron_ore"},
        {pos: [1, 11, 7], state: "minecraft:dirt"},
        {pos: [2, 11, 2], state: "minecraft:grass"},
        {pos: [2, 11, 3], state: "minecraft:grass_block{snowy:false}"},
        {pos: [2, 11, 4], state: "minecraft:torch"},
        {pos: [2, 11, 5], state: "minecraft:poppy"},
        {pos: [2, 11, 6], state: "minecraft:grass_block{snowy:false}"},
        {pos: [2, 11, 7], state: "minecraft:grass_block{snowy:false}"},
        {pos: [2, 11, 8], state: "minecraft:dirt"},
        {pos: [3, 11, 1], state: "minecraft:tall_grass{half:lower}"},
        {pos: [3, 11, 2], state: "minecraft:tall_grass{half:lower}"},
        {pos: [3, 11, 4], state: "minecraft:potatoes{age:7}"},
        {pos: [3, 11, 5], state: "minecraft:grass"},
        {pos: [3, 11, 6], state: "minecraft:tall_grass{half:lower}"},
        {pos: [3, 11, 7], state: "minecraft:grass_block{snowy:false}"},
        {pos: [3, 11, 8], state: "minecraft:tall_grass{half:lower}"},
        {pos: [4, 11, 1], state: "minecraft:grass"},
        {pos: [4, 11, 2], state: "minecraft:tall_grass{half:lower}"},
        {pos: [4, 11, 3], state: "minecraft:potatoes{age:7}"},
        {pos: [4, 11, 5], state: "minecraft:potatoes{age:7}"},
        {pos: [4, 11, 7], state: "minecraft:grass"},
        {pos: [5, 11, 2], state: "minecraft:tall_grass{half:lower}"},
        {pos: [5, 11, 3], state: "minecraft:grass"},
        {pos: [5, 11, 4], state: "minecraft:potatoes{age:7}"},
        {pos: [5, 11, 5], state: "minecraft:grass"},
        {pos: [5, 11, 6], state: "minecraft:dandelion"},
        {pos: [6, 11, 3], state: "minecraft:dandelion"},
        {pos: [6, 11, 5], state: "minecraft:tall_grass{half:lower}"},
        {pos: [7, 11, 3], state: "minecraft:tall_grass{half:upper}"},
        {pos: [7, 11, 4], state: "minecraft:oak_log{axis:y}"},
        {pos: [0, 12, 3], state: "minecraft:grass_block{snowy:false}"},
        {pos: [0, 12, 4], state: "minecraft:cornflower"},
        {pos: [0, 12, 5], state: "minecraft:grass_block{snowy:false}"},
        {pos: [0, 12, 6], state: "minecraft:grass_block{snowy:false}"},
        {pos: [1, 12, 3], state: "minecraft:grass_block{snowy:false}"},
        {pos: [1, 12, 4], state: "minecraft:dark_oak_sign{rotation:12,waterlogged:false}", nbt: {Color: "black", GlowingText: 1b, Text1: '{"text":"Welcome to"}', Text2: '{"text":"Potato Island!"}', Text3: '{"text":"Everything you"}', Text4: '{"text":"need to start!"}', id: "minecraft:sign"}},
        {pos: [1, 12, 6], state: "minecraft:grass_block{snowy:false}"},
        {pos: [1, 12, 7], state: "minecraft:grass_block{snowy:false}"},
        {pos: [2, 12, 3], state: "minecraft:grass"},
        {pos: [2, 12, 6], state: "minecraft:grass"},
        {pos: [2, 12, 8], state: "minecraft:grass_block{snowy:false}"},
        {pos: [3, 12, 1], state: "minecraft:tall_grass{half:upper}"},
        {pos: [3, 12, 2], state: "minecraft:tall_grass{half:upper}"},
        {pos: [3, 12, 6], state: "minecraft:tall_grass{half:upper}"},
        {pos: [3, 12, 8], state: "minecraft:tall_grass{half:upper}"},
        {pos: [4, 12, 2], state: "minecraft:tall_grass{half:upper}"},
        {pos: [5, 12, 2], state: "minecraft:tall_grass{half:upper}"},
        {pos: [6, 12, 5], state: "minecraft:tall_grass{half:upper}"},
        {pos: [7, 12, 4], state: "minecraft:oak_log{axis:y}"},
        {pos: [0, 13, 3], state: "minecraft:dandelion"},
        {pos: [0, 13, 5], state: "minecraft:grass"},
        {pos: [0, 13, 6], state: "minecraft:grass"},
        {pos: [1, 13, 3], state: "minecraft:tall_grass{half:lower}"},
        {pos: [1, 13, 6], state: "minecraft:tall_grass{half:lower}"},
        {pos: [1, 13, 7], state: "minecraft:poppy"},
        {pos: [2, 13, 8], state: "minecraft:tall_grass{half:lower}"},
        {pos: [5, 13, 3], state: "minecraft:oak_leaves{distance:3,persistent:false,waterlogged:false}"},
        {pos: [5, 13, 4], state: "minecraft:oak_leaves{distance:2,persistent:false,waterlogged:false}"},
        {pos: [5, 13, 5], state: "minecraft:oak_leaves{distance:3,persistent:false,waterlogged:false}"},
        {pos: [6, 13, 2], state: "minecraft:oak_leaves{distance:3,persistent:false,waterlogged:false}"},
        {pos: [6, 13, 3], state: "minecraft:oak_leaves{distance:2,persistent:false,waterlogged:false}"},
        {pos: [6, 13, 4], state: "minecraft:oak_leaves{distance:1,persistent:false,waterlogged:false}"},
        {pos: [6, 13, 5], state: "minecraft:oak_leaves{distance:2,persistent:false,waterlogged:false}"},
        {pos: [6, 13, 6], state: "minecraft:oak_leaves{distance:3,persistent:false,waterlogged:false}"},
        {pos: [7, 13, 2], state: "minecraft:oak_leaves{distance:2,persistent:false,waterlogged:false}"},
        {pos: [7, 13, 3], state: "minecraft:oak_leaves{distance:1,persistent:false,waterlogged:false}"},
        {pos: [7, 13, 4], state: "minecraft:oak_log{axis:y}"},
        {pos: [7, 13, 5], state: "minecraft:oak_leaves{distance:1,persistent:false,waterlogged:false}"},
        {pos: [7, 13, 6], state: "minecraft:oak_leaves{distance:2,persistent:false,waterlogged:false}"},
        {pos: [8, 13, 2], state: "minecraft:oak_leaves{distance:3,persistent:false,waterlogged:false}"},
        {pos: [8, 13, 3], state: "minecraft:oak_leaves{distance:2,persistent:false,waterlogged:false}"},
        {pos: [8, 13, 4], state: "minecraft:oak_leaves{distance:1,persistent:false,waterlogged:false}"},
        {pos: [8, 13, 5], state: "minecraft:oak_leaves{distance:2,persistent:false,waterlogged:false}"},
        {pos: [8, 13, 6], state: "minecraft:oak_leaves{distance:3,persistent:false,waterlogged:false}"},
        {pos: [9, 13, 2], state: "minecraft:oak_leaves{distance:4,persistent:false,waterlogged:false}"},
        {pos: [9, 13, 3], state: "minecraft:oak_leaves{distance:3,persistent:false,waterlogged:false}"},
        {pos: [9, 13, 4], state: "minecraft:oak_leaves{distance:2,persistent:false,waterlogged:false}"},
        {pos: [9, 13, 5], state: "minecraft:oak_leaves{distance:3,persistent:false,waterlogged:false}"},
        {pos: [9, 13, 6], state: "minecraft:oak_leaves{distance:4,persistent:false,waterlogged:false}"},
        {pos: [1, 14, 3], state: "minecraft:tall_grass{half:upper}"},
        {pos: [1, 14, 6], state: "minecraft:tall_grass{half:upper}"},
        {pos: [2, 14, 8], state: "minecraft:tall_grass{half:upper}"},
        {pos: [5, 14, 2], state: "minecraft:oak_leaves{distance:4,persistent:false,waterlogged:false}"},
        {pos: [5, 14, 3], state: "minecraft:oak_leaves{distance:3,persistent:false,waterlogged:false}"},
        {pos: [5, 14, 4], state: "minecraft:oak_leaves{distance:2,persistent:false,waterlogged:false}"},
        {pos: [5, 14, 5], state: "minecraft:oak_leaves{distance:3,persistent:false,waterlogged:false}"},
        {pos: [5, 14, 6], state: "minecraft:oak_leaves{distance:4,persistent:false,waterlogged:false}"},
        {pos: [6, 14, 2], state: "minecraft:oak_leaves{distance:3,persistent:false,waterlogged:false}"},
        {pos: [6, 14, 3], state: "minecraft:oak_leaves{distance:2,persistent:false,waterlogged:false}"},
        {pos: [6, 14, 4], state: "minecraft:oak_leaves{distance:1,persistent:false,waterlogged:false}"},
        {pos: [6, 14, 5], state: "minecraft:oak_leaves{distance:2,persistent:false,waterlogged:false}"},
        {pos: [6, 14, 6], state: "minecraft:oak_leaves{distance:3,persistent:false,waterlogged:false}"},
        {pos: [7, 14, 2], state: "minecraft:oak_leaves{distance:2,persistent:false,waterlogged:false}"},
        {pos: [7, 14, 3], state: "minecraft:oak_leaves{distance:1,persistent:false,waterlogged:false}"},
        {pos: [7, 14, 4], state: "minecraft:oak_log{axis:y}"},
        {pos: [7, 14, 5], state: "minecraft:oak_leaves{distance:1,persistent:false,waterlogged:false}"},
        {pos: [7, 14, 6], state: "minecraft:oak_leaves{distance:2,persistent:false,waterlogged:false}"},
        {pos: [8, 14, 2], state: "minecraft:oak_leaves{distance:3,persistent:false,waterlogged:false}"},
        {pos: [8, 14, 3], state: "minecraft:oak_leaves{distance:2,persistent:false,waterlogged:false}"},
        {pos: [8, 14, 4], state: "minecraft:oak_leaves{distance:1,persistent:false,waterlogged:false}"},
        {pos: [8, 14, 5], state: "minecraft:oak_leaves{distance:2,persistent:false,waterlogged:false}"},
        {pos: [8, 14, 6], state: "minecraft:oak_leaves{distance:3,persistent:false,waterlogged:false}"},
        {pos: [9, 14, 2], state: "minecraft:oak_leaves{distance:4,persistent:false,waterlogged:false}"},
        {pos: [9, 14, 3], state: "minecraft:oak_leaves{distance:3,persistent:true,waterlogged:false}"},
        {pos: [9, 14, 4], state: "minecraft:oak_leaves{distance:2,persistent:false,waterlogged:false}"},
        {pos: [9, 14, 5], state: "minecraft:oak_leaves{distance:3,persistent:false,waterlogged:false}"},
        {pos: [9, 14, 6], state: "minecraft:oak_leaves{distance:4,persistent:false,waterlogged:false}"},
        {pos: [6, 15, 3], state: "minecraft:oak_leaves{distance:2,persistent:false,waterlogged:false}"},
        {pos: [6, 15, 4], state: "minecraft:oak_leaves{distance:1,persistent:false,waterlogged:false}"},
        {pos: [6, 15, 5], state: "minecraft:oak_leaves{distance:2,persistent:false,waterlogged:false}"},
        {pos: [7, 15, 3], state: "minecraft:oak_leaves{distance:1,persistent:false,waterlogged:false}"},
        {pos: [7, 15, 4], state: "minecraft:oak_log{axis:y}"},
        {pos: [7, 15, 5], state: "minecraft:oak_leaves{distance:1,persistent:false,waterlogged:false}"},
        {pos: [8, 15, 3], state: "minecraft:oak_leaves{distance:2,persistent:false,waterlogged:false}"},
        {pos: [8, 15, 4], state: "minecraft:oak_leaves{distance:1,persistent:false,waterlogged:false}"},
        {pos: [8, 15, 5], state: "minecraft:oak_leaves{distance:2,persistent:false,waterlogged:false}"},
        {pos: [6, 16, 4], state: "minecraft:oak_leaves{distance:2,persistent:false,waterlogged:false}"},
        {pos: [7, 16, 3], state: "minecraft:oak_leaves{distance:2,persistent:false,waterlogged:false}"},
        {pos: [7, 16, 4], state: "minecraft:oak_leaves{distance:1,persistent:false,waterlogged:false}"},
        {pos: [7, 16, 5], state: "minecraft:oak_leaves{distance:2,persistent:false,waterlogged:false}"},
        {pos: [8, 16, 4], state: "minecraft:oak_leaves{distance:2,persistent:false,waterlogged:false}"}
    ],
    entities: [
        {blockPos: [1, 13, 4], pos: [1.5260751296883184d, 13.0d, 4.198338340372741d], nbt: {AbsorptionAmount: 0.0f, Age: 1, Air: 300s, ArmorDropChances: [0.085f, 0.085f, 0.085f, 0.085f], ArmorItems: [{}, {}, {}, {}], Attributes: [{Base: 0.08d, Name: "forge:entity_gravity"}, {Base: 0.23000000417232513d, Name: "minecraft:generic.movement_speed"}, {Base: 0.0d, Name: "forge:step_height_addition"}], Brain: {memories: {}}, CanPickUpLoot: 0b, CanUpdate: 1b, Color: 0b, DeathTime: 0s, FallDistance: 0.0f, FallFlying: 0b, Fire: 0s, ForcedAge: 0, ForgeData: {}, HandDropChances: [0.085f, 0.085f], HandItems: [{}, {}], Health: 8.0f, HurtByTimestamp: 0, HurtTime: 0s, InLove: 0, Invulnerable: 0b, LeftHanded: 0b, Motion: [0.0d, 0.0d, 0.0d], OnGround: 1b, PersistenceRequired: 0b, PortalCooldown: 0, Pos: [-2.4739248703116816d, 67.0d, 0.19833834037274126d], Rotation: [-198.28125f, 0.0f], Sheared: 0b, UUID: [I; -358270162, -1823652213, -2064593351, 1974228315], id: "minecraft:sheep"}},
        {blockPos: [1, 12, 5], pos: [1.03125d, 12.5d, 5.5d], nbt: {Air: 300s, CanUpdate: 1b, Facing: 5b, FallDistance: 0.0f, Fire: -1s, Fixed: 0b, ForgeData: {}, Invisible: 0b, Invulnerable: 0b, Item: {Count: 1b, id: "minecraft:writable_book", tag: {pages: ["Resources on Potato Island are limited. Do not throw anything away! If you are careful and think about what you are doing, there are enough resources to get you up and going.

Good Luck and Have Fun!

CM"]}}, ItemDropChance: 1.0f, ItemRotation: 0b, Motion: [0.0d, 0.0d, 0.0d], OnGround: 0b, PortalCooldown: 0, Pos: [-2.96875d, 66.5d, 1.5d], Rotation: [270.0f, 0.0f], TileX: -3, TileY: 66, TileZ: 1, UUID: [I; -1959811697, 56774103, -1955770786, -554097897], id: "minecraft:glow_item_frame"}}
    ],
    palette: [
        "minecraft:stone",
        "create:zinc_ore",
        "minecraft:gravel",
        "minecraft:iron_ore",
        "minecraft:coal_ore",
        "minecraft:andesite",
        "minecraft:diorite",
        "minecraft:bedrock",
        "minecraft:dripstone_block",
        "minecraft:clay",
        "minecraft:dirt",
        "minecraft:sand",
        "minecraft:grass_block{snowy:false}",
        "minecraft:oak_log{axis:y}",
        "minecraft:oak_leaves{distance:3,persistent:false,waterlogged:false}",
        "minecraft:oak_leaves{distance:2,persistent:false,waterlogged:false}",
        "minecraft:oak_leaves{distance:1,persistent:false,waterlogged:false}",
        "minecraft:oak_leaves{distance:4,persistent:false,waterlogged:false}",
        "minecraft:oak_leaves{distance:3,persistent:true,waterlogged:false}",
        "minecraft:water{level:8}",
        "minecraft:vine{east:true,north:false,south:false,up:false,west:false}",
        "minecraft:cobweb",
        "minecraft:vine{east:false,north:false,south:false,up:false,west:true}",
        "minecraft:vine{east:false,north:false,south:true,up:false,west:false}",
        "minecraft:vine{east:true,north:true,south:false,up:true,west:false}",
        "minecraft:lava{level:0}",
        "minecraft:vine{east:false,north:false,south:false,up:true,west:false}",
        "minecraft:pointed_dripstone{thickness:tip,vertical_direction:down,waterlogged:false}",
        "minecraft:vine{east:false,north:false,south:true,up:true,west:false}",
        "minecraft:vine{east:false,north:false,south:false,up:true,west:true}",
        "minecraft:vine{east:true,north:false,south:true,up:false,west:false}",
        "minecraft:water{level:1}",
        "minecraft:water{level:0}",
        "minecraft:vine{east:true,north:false,south:true,up:true,west:false}",
        "minecraft:farmland{moisture:7}",
        "minecraft:grass",
        "minecraft:tall_grass{half:lower}",
        "minecraft:torch",
        "minecraft:poppy",
        "minecraft:potatoes{age:7}",
        "minecraft:dandelion",
        "minecraft:tall_grass{half:upper}",
        "minecraft:cornflower",
        "minecraft:dark_oak_sign{rotation:12,waterlogged:false}"
    ]
}